<html>
<head> Exception Handling</br></head>
<body>
<script>
try{
var a= ["34","32","5","31","24","44","67"]; //a is an array
document.write(a+"<br>");    // displays elements of a
document.write(b); //b is undefined but still trying to fetch its value. Thus catch block will be invoked
}catch(e){
alert("There is error which shows "+e.message); //Handling error
}
// finally{
//   document.write("Welcome");
// }
</script>
<!-- <br>
<br>
<p>Example of throw using try</p>
<script>
    try {
       throw new Error('This is the throw keyword'); //user-defined throw statement.
    }
    catch (e) {
      document.write(e.message); // This will generate an error message
    }
    </script> -->
    <script>
      //  let e = Number(prompt("enter the first no"));
      //   let f = Number(prompt("enter the second no"));
      //   function fun2(g,h){
      //       try{
      //           if(g==""||h==""){
      //               throw new Error("No input is given");
      //           }
      //           else{
      //       var i=g+h;
      //           }
            
      //       document.write("Addition of two numbers is :"+i);
      //       }
      //       catch(e){
      //           document.write(e.message+"<br>");
      //       }
      //       finally{
      //           document.write("Finally block is always executed");
      //       }
      //   }
      //   fun2(e,f);
    </script>
</body>
</html>

 
